[2018-04-22 21:45:55,679][15088][testexample2.py:11][INFO]:setUp begin
[2018-04-22 21:45:55,682][15088][testexample2.py:15][INFO]:setUp end
[2018-04-22 21:45:55,684][15088][testexample2.py:26][INFO]:TestAuthed2.testCode
[2018-04-22 21:45:55,687][15088][testexample2.py:27][INFO]:测试:xxxxxxxxxxxxxx
[2018-04-22 21:45:55,691][15088][logger.py:37][INFO]:F
[2018-04-22 21:45:55,691][15088][testexample2.py:35][INFO]:tearDown begin
[2018-04-22 21:45:55,694][15088][testexample2.py:37][INFO]:tearDown end
[2018-04-22 21:45:55,694][15088][testexample2.py:11][INFO]:setUp begin
[2018-04-22 21:45:55,695][15088][testexample2.py:15][INFO]:setUp end
[2018-04-22 21:45:55,695][15088][testexample2.py:18][INFO]:TestAuthed2.testStatus
[2018-04-22 21:45:55,695][15088][testexample2.py:19][INFO]:测试:xxxxxxxxxxxx
[2018-04-22 21:46:00,696][15088][testexample2.py:35][INFO]:tearDown begin
[2018-04-22 21:46:00,696][15088][testexample2.py:37][INFO]:tearDown end
[2018-04-22 21:46:00,697][15088][logger.py:37][INFO]:.
[2018-04-22 21:46:00,697][15088][logger.py:37][INFO]:

[2018-04-22 21:46:00,697][15088][logger.py:37][INFO]:======================================================================
[2018-04-22 21:46:00,697][15088][logger.py:37][INFO]:

[2018-04-22 21:46:00,698][15088][logger.py:37][INFO]:FAIL: testCode (testexample2.TestAuthed2)
[2018-04-22 21:46:00,698][15088][logger.py:37][INFO]:

[2018-04-22 21:46:00,698][15088][logger.py:37][INFO]:----------------------------------------------------------------------
[2018-04-22 21:46:00,698][15088][logger.py:37][INFO]:

[2018-04-22 21:46:00,698][15088][logger.py:37][INFO]:Traceback (most recent call last):
  File "/Users/bj-m-206380a/Documents/workspace/demos/testcases/testexample2.py", line 31, in testCode
    assert 2==1
AssertionError

[2018-04-22 21:46:00,698][15088][logger.py:37][INFO]:

[2018-04-22 21:46:00,699][15088][logger.py:37][INFO]:----------------------------------------------------------------------
[2018-04-22 21:46:00,699][15088][logger.py:37][INFO]:

[2018-04-22 21:46:00,699][15088][logger.py:37][INFO]:Ran 2 tests in 5.019s
[2018-04-22 21:46:00,699][15088][logger.py:37][INFO]:

[2018-04-22 21:46:00,699][15088][logger.py:37][INFO]:

[2018-04-22 21:46:00,699][15088][logger.py:37][INFO]:FAILED
[2018-04-22 21:46:00,700][15088][logger.py:37][INFO]: (failures=1)
[2018-04-22 21:46:00,700][15088][logger.py:37][INFO]:

